<?xml version="1.0" ?>
<!-- =================================================================================== -->
<!-- |    This document was autogenerated by xacro from scott_assembled.urdf.xacro     | -->
<!-- |    EDITING THIS FILE BY HAND IS NOT RECOMMENDED                                 | -->
<!-- =================================================================================== -->
<robot name="gummi" xmlns:xacro="http://www.ros.org/wiki/xacro">
  <!-- <xacro:include filename="package://scott_description/urdf/scott_torso.urdf.xacro" />
<xacro:include filename="package://scott_description/urdf/scott_legs.urdf.xacro" /> -->
  <link name="base_link"/>
  <joint name="set_worldaxis" type="fixed">
    <origin rpy="1.570796326795 0 0" xyz="0.0 0.0 0.5199899999999991"/>
    <parent link="base_link"/>
    <child link="torso"/>
    <axis xyz="0 0 0"/>
    <limit effort="0" lower="-1" upper="1" velocity="0"/>
  </joint>
  <link name="torso">
    <inertial>
      <origin rpy="0.0 0.0 0.0" xyz="0.0 0.0 0.0"/>
      <mass value="0"/>
      <inertia ixx="0" ixy="0" ixz="0" iyy="0" iyz="0" izz="0"/>
    </inertial>
    <visual>
      <origin rpy="0.0 0.0 0.0" xyz="0.0 0.0 0.0"/>
      <geometry>
        <mesh filename="package://scott_description/meshes/torso.stl"/>
      </geometry>
      <material name="">
        <color rgba="0.792156862745098 0.819607843137255 0.933333333333333 1"/>
      </material>
    </visual>
    <collision>
      <origin rpy="0.0 0.0 0.0" xyz="0.0 0.0 0.0"/>
      <geometry>
        <mesh filename="package://scott_description/meshes/torso.stl"/>
      </geometry>
    </collision>
  </link>
  <!-- Begin macro here so there is only one instance of torso link generated -->
  <!-- Joints to limbs -->
  <joint name="torso_to_right_leg" type="fixed">
    <!-- <origin rpy="0.0 0.0 0.0" xyz="${reflect*0.0356} 0.0 -0.0130"/> -->
    <origin rpy="0.0 0.0 0.0" xyz="0.0 0.0 0.0"/>
    <parent link="torso"/>
    <child link="right_leg_L1"/>
    <axis xyz="0 0 0"/>
    <limit effort="0" lower="-1" upper="1" velocity="0"/>
  </joint>
  <!-- USE THE REFLECT MACRO TO JUST MIRROR THE RIGHT LEG -->
  <!-- http://wiki.ros.org/urdf/Tutorials/Using%20Xacro%20to%20Clean%20Up%20a%20URDF%20File#Leg_macro -->
  <!-- Joints to limbs -->
  <joint name="torso_to_left_leg" type="fixed">
    <!-- <origin rpy="0.0 0.0 0.0" xyz="${reflect*0.0356} 0.0 -0.0130"/> -->
    <origin rpy="0.0 0.0 0.0" xyz="-0.0712083 0.0 0.0"/>
    <parent link="torso"/>
    <child link="left_leg_L1"/>
    <axis xyz="0 0 0"/>
    <limit effort="0" lower="-1" upper="1" velocity="0"/>
  </joint>
  <!-- USE THE REFLECT MACRO TO JUST MIRROR THE RIGHT LEG -->
  <!-- http://wiki.ros.org/urdf/Tutorials/Using%20Xacro%20to%20Clean%20Up%20a%20URDF%20File#Leg_macro -->
  <link name="right_leg_L1">
    <inertial>
      <origin rpy="0.0 0.0 0.0" xyz="0.0 0.0 0.0"/>
      <mass value="0"/>
      <inertia ixx="0" ixy="0" ixz="0" iyy="0" iyz="0" izz="0"/>
    </inertial>
    <visual>
      <origin rpy="0.0 0.0 0.0" xyz="0.0 0.0 0.0"/>
      <geometry>
        <mesh filename="package://scott_description/meshes/right_leg/link1.stl"/>
      </geometry>
      <material name="">
        <color rgba="0.792156862745098 0.819607843137255 0.933333333333333 1"/>
      </material>
    </visual>
    <collision>
      <origin rpy="0.0 0.0 0.0" xyz="0.0 0.0 0.0"/>
      <geometry>
        <mesh filename="package://scott_description/meshes/right_leg/link1.stl"/>
      </geometry>
    </collision>
  </link>
  <link name="right_leg_L2">
    <inertial>
      <origin rpy="0.0 0.0 0.0" xyz="0.0 0.0 0.0"/>
      <mass value="0"/>
      <inertia ixx="0" ixy="0" ixz="0" iyy="0" iyz="0" izz="0"/>
    </inertial>
    <visual>
      <origin rpy="0.0 0.0 0.0" xyz="0.0 0.0 0.0"/>
      <geometry>
        <mesh filename="package://scott_description/meshes/right_leg/link2.stl"/>
      </geometry>
      <material name="">
        <color rgba="0.792156862745098 0.819607843137255 0.933333333333333 1"/>
      </material>
    </visual>
    <collision>
      <origin rpy="0.0 0.0 0.0" xyz="0.0 0.0 0.0"/>
      <geometry>
        <mesh filename="package://scott_description/meshes/right_leg/link2.stl"/>
      </geometry>
    </collision>
  </link>
  <link name="right_leg_L3">
    <inertial>
      <origin rpy="0.0 0.0 0.0" xyz="0.0 0.0 0.0"/>
      <mass value="0"/>
      <inertia ixx="0" ixy="0" ixz="0" iyy="0" iyz="0" izz="0"/>
    </inertial>
    <visual>
      <origin rpy="0.0 0.0 0.0" xyz="0.0 0.0 0.0"/>
      <geometry>
        <mesh filename="package://scott_description/meshes/right_leg/link3.stl"/>
      </geometry>
      <material name="">
        <color rgba="0.792156862745098 0.819607843137255 0.933333333333333 1"/>
      </material>
    </visual>
    <collision>
      <origin rpy="0.0 0.0 0.0" xyz="0.0 0.0 0.0"/>
      <geometry>
        <mesh filename="package://scott_description/meshes/right_leg/link3.stl"/>
      </geometry>
    </collision>
  </link>
  <link name="right_leg_L4">
    <inertial>
      <origin rpy="0.0 0.0 0.0" xyz="0.0 0.0 0.0"/>
      <mass value="0"/>
      <inertia ixx="0" ixy="0" ixz="0" iyy="0" iyz="0" izz="0"/>
    </inertial>
    <visual>
      <origin rpy="0.0 0.0 0.0" xyz="0.0 0.0 0.0"/>
      <geometry>
        <mesh filename="package://scott_description/meshes/right_leg/link4.stl"/>
      </geometry>
      <material name="">
        <color rgba="0.792156862745098 0.819607843137255 0.933333333333333 1"/>
      </material>
    </visual>
    <collision>
      <origin rpy="0.0 0.0 0.0" xyz="0.0 0.0 0.0"/>
      <geometry>
        <mesh filename="package://scott_description/meshes/right_leg/link4.stl"/>
      </geometry>
    </collision>
  </link>
  <link name="right_leg_L5">
    <inertial>
      <origin rpy="0.0 0.0 0.0" xyz="0.0 0.0 0.0"/>
      <mass value="0"/>
      <inertia ixx="0" ixy="0" ixz="0" iyy="0" iyz="0" izz="0"/>
    </inertial>
    <visual>
      <origin rpy="0.0 0.0 0.0" xyz="0.0 0.0 0.0"/>
      <geometry>
        <mesh filename="package://scott_description/meshes/right_leg/link5.stl"/>
      </geometry>
      <material name="">
        <color rgba="0.792156862745098 0.819607843137255 0.933333333333333 1"/>
      </material>
    </visual>
    <collision>
      <origin rpy="0.0 0.0 0.0" xyz="0.0 0.0 0.0"/>
      <geometry>
        <mesh filename="package://scott_description/meshes/right_leg/link5.stl"/>
      </geometry>
    </collision>
  </link>
  <link name="right_leg_L6">
    <inertial>
      <origin rpy="0.0 0.0 0.0" xyz="0.0 0.0 0.0"/>
      <mass value="0"/>
      <inertia ixx="0" ixy="0" ixz="0" iyy="0" iyz="0" izz="0"/>
    </inertial>
    <visual>
      <origin rpy="0.0 0.0 0.0" xyz="0.0 0.0 0.0"/>
      <geometry>
        <mesh filename="package://scott_description/meshes/right_leg/link6.stl"/>
      </geometry>
      <material name="">
        <color rgba="0.792156862745098 0.819607843137255 0.933333333333333 1"/>
      </material>
    </visual>
    <collision>
      <origin rpy="0.0 0.0 0.0" xyz="0.0 0.0 0.0"/>
      <geometry>
        <mesh filename="package://scott_description/meshes/right_leg/link6.stl"/>
      </geometry>
    </collision>
  </link>
  <link name="right_foot">
    <inertial>
      <origin rpy="0.0 0.0 0.0" xyz="0.0 0.0 0.0"/>
      <mass value="0"/>
      <inertia ixx="0" ixy="0" ixz="0" iyy="0" iyz="0" izz="0"/>
    </inertial>
    <visual>
      <origin rpy="0.0 0.0 0.0" xyz="0.0 0.0 0.0"/>
      <geometry>
        <mesh filename="package://scott_description/meshes/right_leg/foot.stl"/>
      </geometry>
      <material name="">
        <color rgba="0.792156862745098 0.819607843137255 0.933333333333333 1"/>
      </material>
    </visual>
    <collision>
      <origin rpy="0.0 0.0 0.0" xyz="0.0 0.0 0.0"/>
      <geometry>
        <mesh filename="package://scott_description/meshes/right_leg/foot.stl"/>
      </geometry>
    </collision>
  </link>
  <!-- Joints -->
  <joint name="right_leg_J1" type="continuous">
    <origin rpy="0.0 0.0 0.0" xyz="0.0205 -0.0275 0.0135"/>
    <parent link="right_leg_L1"/>
    <child link="right_leg_L2"/>
    <axis xyz="0.0 1.0 0.0"/>
    <limit effort="0" lower="-1" upper="1" velocity="0"/>
  </joint>
  <joint name="right_leg_J2" type="continuous">
    <origin rpy="0.0 0.0 0.0" xyz="0.0 -0.0390 -0.0280"/>
    <parent link="right_leg_L2"/>
    <child link="right_leg_L3"/>
    <axis xyz="0.0 0.0 -1.0"/>
    <limit effort="0" lower="-1" upper="1" velocity="0"/>
  </joint>
  <joint name="right_leg_J3" type="continuous">
    <origin rpy="0.0 0.0 0.0" xyz="-0.0305 0.0 0.0350"/>
    <parent link="right_leg_L3"/>
    <child link="right_leg_L4"/>
    <axis xyz="-1.0 0.0 0.0"/>
    <limit effort="0" lower="-1" upper="1" velocity="0"/>
  </joint>
  <joint name="right_leg_J4" type="continuous">
    <origin rpy="0.0 0.0 0.0" xyz="0.0 -0.2011 -0.0106"/>
    <parent link="right_leg_L4"/>
    <child link="right_leg_L5"/>
    <axis xyz="1.0 0.0 0.0"/>
    <limit effort="0" lower="-1" upper="1" velocity="0"/>
  </joint>
  <joint name="right_leg_J5" type="continuous">
    <origin rpy="0.0 0.0 0.0" xyz="0.00102 -0.2074 -0.0419"/>
    <parent link="right_leg_L5"/>
    <child link="right_leg_L6"/>
    <axis xyz="1.0 0.0 0.0"/>
    <limit effort="0" lower="-1" upper="1" velocity="0"/>
  </joint>
  <joint name="right_leg_J6" type="continuous">
    <origin rpy="0.0 0.0 0.0" xyz="0.0295 0.0 -0.032"/>
    <parent link="right_leg_L6"/>
    <child link="right_foot"/>
    <axis xyz="0.0 0.0 -1.0"/>
    <limit effort="0" lower="-1" upper="1" velocity="0"/>
  </joint>
  <link name="left_leg_L1">
    <inertial>
      <origin rpy="0.0 0.0 0.0" xyz="0.0 0.0 0.0"/>
      <mass value="0"/>
      <inertia ixx="0" ixy="0" ixz="0" iyy="0" iyz="0" izz="0"/>
    </inertial>
    <visual>
      <origin rpy="0.0 0.0 0.0" xyz="0.0 0.0 0.0"/>
      <geometry>
        <mesh filename="package://scott_description/meshes/left_leg/link1.stl"/>
      </geometry>
      <material name="">
        <color rgba="0.792156862745098 0.819607843137255 0.933333333333333 1"/>
      </material>
    </visual>
    <collision>
      <origin rpy="0.0 0.0 0.0" xyz="0.0 0.0 0.0"/>
      <geometry>
        <mesh filename="package://scott_description/meshes/left_leg/link1.stl"/>
      </geometry>
    </collision>
  </link>
  <link name="left_leg_L2">
    <inertial>
      <origin rpy="0.0 0.0 0.0" xyz="0.0 0.0 0.0"/>
      <mass value="0"/>
      <inertia ixx="0" ixy="0" ixz="0" iyy="0" iyz="0" izz="0"/>
    </inertial>
    <visual>
      <origin rpy="0.0 0.0 0.0" xyz="0.0 0.0 0.0"/>
      <geometry>
        <mesh filename="package://scott_description/meshes/left_leg/link2.stl"/>
      </geometry>
      <material name="">
        <color rgba="0.792156862745098 0.819607843137255 0.933333333333333 1"/>
      </material>
    </visual>
    <collision>
      <origin rpy="0.0 0.0 0.0" xyz="0.0 0.0 0.0"/>
      <geometry>
        <mesh filename="package://scott_description/meshes/left_leg/link2.stl"/>
      </geometry>
    </collision>
  </link>
  <link name="left_leg_L3">
    <inertial>
      <origin rpy="0.0 0.0 0.0" xyz="0.0 0.0 0.0"/>
      <mass value="0"/>
      <inertia ixx="0" ixy="0" ixz="0" iyy="0" iyz="0" izz="0"/>
    </inertial>
    <visual>
      <origin rpy="0.0 0.0 0.0" xyz="0.0 0.0 0.0"/>
      <geometry>
        <mesh filename="package://scott_description/meshes/left_leg/link3.stl"/>
      </geometry>
      <material name="">
        <color rgba="0.792156862745098 0.819607843137255 0.933333333333333 1"/>
      </material>
    </visual>
    <collision>
      <origin rpy="0.0 0.0 0.0" xyz="0.0 0.0 0.0"/>
      <geometry>
        <mesh filename="package://scott_description/meshes/left_leg/link3.stl"/>
      </geometry>
    </collision>
  </link>
  <link name="left_leg_L4">
    <inertial>
      <origin rpy="0.0 0.0 0.0" xyz="0.0 0.0 0.0"/>
      <mass value="0"/>
      <inertia ixx="0" ixy="0" ixz="0" iyy="0" iyz="0" izz="0"/>
    </inertial>
    <visual>
      <origin rpy="0.0 0.0 0.0" xyz="0.0 0.0 0.0"/>
      <geometry>
        <mesh filename="package://scott_description/meshes/left_leg/link4.stl"/>
      </geometry>
      <material name="">
        <color rgba="0.792156862745098 0.819607843137255 0.933333333333333 1"/>
      </material>
    </visual>
    <collision>
      <origin rpy="0.0 0.0 0.0" xyz="0.0 0.0 0.0"/>
      <geometry>
        <mesh filename="package://scott_description/meshes/left_leg/link4.stl"/>
      </geometry>
    </collision>
  </link>
  <link name="left_leg_L5">
    <inertial>
      <origin rpy="0.0 0.0 0.0" xyz="0.0 0.0 0.0"/>
      <mass value="0"/>
      <inertia ixx="0" ixy="0" ixz="0" iyy="0" iyz="0" izz="0"/>
    </inertial>
    <visual>
      <origin rpy="0.0 0.0 0.0" xyz="0.0 0.0 0.0"/>
      <geometry>
        <mesh filename="package://scott_description/meshes/left_leg/link5.stl"/>
      </geometry>
      <material name="">
        <color rgba="0.792156862745098 0.819607843137255 0.933333333333333 1"/>
      </material>
    </visual>
    <collision>
      <origin rpy="0.0 0.0 0.0" xyz="0.0 0.0 0.0"/>
      <geometry>
        <mesh filename="package://scott_description/meshes/left_leg/link5.stl"/>
      </geometry>
    </collision>
  </link>
  <link name="left_leg_L6">
    <inertial>
      <origin rpy="0.0 0.0 0.0" xyz="0.0 0.0 0.0"/>
      <mass value="0"/>
      <inertia ixx="0" ixy="0" ixz="0" iyy="0" iyz="0" izz="0"/>
    </inertial>
    <visual>
      <origin rpy="0.0 0.0 0.0" xyz="0.0 0.0 0.0"/>
      <geometry>
        <mesh filename="package://scott_description/meshes/left_leg/link6.stl"/>
      </geometry>
      <material name="">
        <color rgba="0.792156862745098 0.819607843137255 0.933333333333333 1"/>
      </material>
    </visual>
    <collision>
      <origin rpy="0.0 0.0 0.0" xyz="0.0 0.0 0.0"/>
      <geometry>
        <mesh filename="package://scott_description/meshes/left_leg/link6.stl"/>
      </geometry>
    </collision>
  </link>
  <link name="left_foot">
    <inertial>
      <origin rpy="0.0 0.0 0.0" xyz="0.0 0.0 0.0"/>
      <mass value="0"/>
      <inertia ixx="0" ixy="0" ixz="0" iyy="0" iyz="0" izz="0"/>
    </inertial>
    <visual>
      <origin rpy="0.0 0.0 0.0" xyz="0.0 0.0 0.0"/>
      <geometry>
        <mesh filename="package://scott_description/meshes/left_leg/foot.stl"/>
      </geometry>
      <material name="">
        <color rgba="0.792156862745098 0.819607843137255 0.933333333333333 1"/>
      </material>
    </visual>
    <collision>
      <origin rpy="0.0 0.0 0.0" xyz="0.0 0.0 0.0"/>
      <geometry>
        <mesh filename="package://scott_description/meshes/left_leg/foot.stl"/>
      </geometry>
    </collision>
  </link>
  <!-- Joints -->
  <joint name="left_leg_J1" type="continuous">
    <origin rpy="0.0 0.0 0.0" xyz="-0.0205 -0.0275 0.0135"/>
    <parent link="left_leg_L1"/>
    <child link="left_leg_L2"/>
    <axis xyz="0.0 1.0 0.0"/>
    <limit effort="0" lower="-1" upper="1" velocity="0"/>
  </joint>
  <joint name="left_leg_J2" type="continuous">
    <origin rpy="0.0 0.0 0.0" xyz="0.0 -0.0390 -0.0280"/>
    <parent link="left_leg_L2"/>
    <child link="left_leg_L3"/>
    <axis xyz="0.0 0.0 -1.0"/>
    <limit effort="0" lower="-1" upper="1" velocity="0"/>
  </joint>
  <joint name="left_leg_J3" type="continuous">
    <origin rpy="0.0 0.0 0.0" xyz="0.0305 0.0 0.0350"/>
    <parent link="left_leg_L3"/>
    <child link="left_leg_L4"/>
    <axis xyz="-1.0 0.0 0.0"/>
    <limit effort="0" lower="-1" upper="1" velocity="0"/>
  </joint>
  <joint name="left_leg_J4" type="continuous">
    <origin rpy="0.0 0.0 0.0" xyz="0.0 -0.2011 -0.0106"/>
    <parent link="left_leg_L4"/>
    <child link="left_leg_L5"/>
    <axis xyz="1.0 0.0 0.0"/>
    <limit effort="0" lower="-1" upper="1" velocity="0"/>
  </joint>
  <joint name="left_leg_J5" type="continuous">
    <origin rpy="0.0 0.0 0.0" xyz="-0.00102 -0.2074 -0.0419"/>
    <parent link="left_leg_L5"/>
    <child link="left_leg_L6"/>
    <axis xyz="1.0 0.0 0.0"/>
    <limit effort="0" lower="-1" upper="1" velocity="0"/>
  </joint>
  <joint name="left_leg_J6" type="continuous">
    <origin rpy="0.0 0.0 0.0" xyz="-0.0295 0.0 0.075"/>
    <parent link="left_leg_L6"/>
    <child link="left_foot"/>
    <axis xyz="0.0 0.0 -1.0"/>
    <limit effort="0" lower="-1" upper="1" velocity="0"/>
  </joint>
</robot>

